<?xml version="1.0"?>
<robot xmlns:xacro="http://www.ros.org/wiki/xacro">
  <xacro:macro name="caster_wheel_joint" params="prefix">
    <joint name="${prefix}_caster_wheel_joint" type="continuous">
      <parent link="${prefix}_caster_swivel_link"/>
      <child link="${prefix}_caster_wheel_link"/>
      <origin xyz="0.03 0.0 -0.065" rpy="${-PI/2} 0 0"/>
      <axis xyz="0 0 1"/>
      <limit effort="0.0" velocity="0.0" lower="-1e15" upper="1e15"/>
      <dynamics damping="0.01"/>
    </joint>
  </xacro:macro>
</robot>
