<?xml version="1.0" ?>
<robot name="orne_box" xmlns:xacro="http://ros.org/wiki/xacro">
  <xacro:include filename="$(find orne_box_description)/urdf/common_properties.xacro"/>
  <xacro:include filename="$(find orne_box_description)/urdf/orne_box.gazebo.xacro"/>

  <link name="base_footprint"/>

  <joint name="base_joint" type="fixed">
    <parent link="base_footprint"/>
    <child link="base_link"/>
    <origin xyz="0.0 0.0 0.152" rpy="0 0 0"/>
  </joint>

  <link name="base_link">
    <visual>
      <origin xyz="0.0 0 -0.152" rpy="0 0 0"/>
      <geometry>
        <mesh filename="package://orne_box_description/meshes/bases/orne_box_base.stl" scale="1 1 1"/>
      </geometry>
      <material name="light_black"/>
    </visual>
    
    <collision>
      <origin xyz="0.158 0 0" rpy="0 0 0"/>
      <geometry>
        <box size="0.540 0.40 0.02"/>
      </geometry>
    </collision>

    <inertial>
      <origin xyz="0 0.07 -0.05" rpy="0 0 0"/>
      <mass value="25.0"/>
      <inertia ixx="0.1" ixy="0.0" ixz="0.0"
               iyy="0.1" iyz="0.0"
               izz="0.1" />
    </inertial>
  </link>

  <joint name="wheel_left_joint" type="continuous">
    <parent link="base_link"/>
    <child link="wheel_left_link"/>
    <origin xyz="0.0 0.23075 0.0" rpy="-1.57 0 0"/>
    <axis xyz="0 0 1"/>
  </joint>

  <link name="wheel_left_link">
    <visual>
      <origin xyz="0 0 0" rpy="0 0 0"/>
      <geometry>
        <mesh filename="package://orne_box_description/meshes/wheels/tire.stl" scale="1 1 1"/>
      </geometry>
      <material name="dark"/>
    </visual>

    <collision>
      <origin xyz="0 0 0" rpy="0 0 0"/>
      <geometry>
        <cylinder length="0.0225" radius="0.152"/>
      </geometry>
    </collision>

    <inertial>
      <origin xyz="0 0 0" />
      <mass value="0.2" />
      <inertia ixx="1.1175580e-05" ixy="-4.2369783e-11" ixz="-5.9381719e-09"
               iyy="1.1192413e-05" iyz="-1.4400107e-11"
               izz="2.0712558e-05" />
    </inertial>

  </link>

  <joint name="wheel_right_joint" type="continuous">
    <parent link="base_link"/>
    <child link="wheel_right_link"/>
    <origin xyz="0.0 -0.23075 0.0" rpy="-1.57 0 0"/>
    <axis xyz="0 0 1"/>
  </joint>

  <link name="wheel_right_link">
    <visual>
      <origin xyz="0 0 0" rpy="0 0 0"/>
      <geometry>
        <mesh filename="package://orne_box_description/meshes/wheels/tire.stl" scale="1 1 1"/>
      </geometry>
      <material name="dark"/>
    </visual>

    <collision>
      <origin xyz="0 0 0" rpy="0 0 0"/>
      <geometry>
        <cylinder length="0.0225" radius="0.152"/>
      </geometry>
    </collision>

      <inertial>
        <origin xyz="0 0 0" />
        <mass value="0.2" />
        <inertia ixx="1.1175580e-05" ixy="-4.2369783e-11" ixz="-5.9381719e-09"
               iyy="1.1192413e-05" iyz="-1.4400107e-11"
               izz="2.0712558e-05" />
      </inertial>

  </link>

  <joint name="caster_front_joint" type="fixed">
    <parent link="base_link"/>
    <child link="caster_front_link"/>
    <origin xyz="0.374295 0 0.015" rpy="-3.14 0 0"/>
  </joint>

  <link name="caster_front_link">
    <collision>
      <origin xyz="0 0.0 0.0835" rpy="0 0 0"/>
      <geometry>
        <box size="0.10 0.4 0.167"/>
      </geometry>
    </collision>

    <inertial>
      <origin xyz="0 0 0" />
      <mass value="0.2" />
      <inertia ixx="0.001" ixy="0.0" ixz="0.0"
               iyy="0.001" iyz="0.0"
               izz="0.001" />
    </inertial>
  </link>

  <joint name="imu_joint" type="fixed">
    <parent link="base_link"/>
    <child link="imu_link"/>
    <origin xyz="0 0 0" rpy="0 0 0"/>
  </joint>

  <link name="imu_link"/>

  <joint name="scan_joint" type="fixed">
    <parent link="base_link"/>
    <child link="base_scan"/>
    <origin xyz="0.374295 0 0.1225" rpy="-3.14 0 0"/>
  </joint>

  <link name="base_scan">

    <inertial>
      <mass value="0.08" />
      <origin xyz="0 0 0" />
      <inertia ixx="0.001" ixy="0.0" ixz="0.0"
               iyy="0.001" iyz="0.0"
               izz="0.001" />
    </inertial>
  </link>

</robot>
